Workbook

Sheet 2H.wke
A1: Date | B1: Time | C1: Row | D1: Identifier 1 | E1: Identifier 2 | F1: Amount | G1: Comment | H1: Peak Nr | I1: Ampl 2 | J1: Area 2 | K1: Ampl 3 | L1: Area 3 | M1: R 3H2/2H2 | N1: d 3H2/2H2
A2: 04/20/26 | B2: 18:12:58 | C2: 1 | D2: Mar | H2: 1 | I2: 2632 | J2: 47.589 | K2: 815 | L2: 0.014 | M2: 0.0003118 | N2: 1.032
A3: 04/20/26 | B3: 18:12:58 | C3: 1 | D3: Mar | H3: 2 | I3: 2633 | J3: 48.739 | K3: 814 | L3: 0.014 | M3: 0.0003115 | N3: 0
A4: 04/20/26 | B4: 18:12:58 | C4: 1 | D4: Mar | H4: 3 | I4: 2766 | J4: 23.81 | K4: 1065 | L4: 0.009 | M4: 0.0003904 | N4: 253.256
A5: 04/20/26 | B5: 18:21:59 | C5: 2 | D5: Mar | H5: 1 | I5: 2645 | J5: 47.895 | K5: 817 | L5: 0.014 | M5: 0.0003113 | N5: -0.555
A6: 04/20/26 | B6: 18:21:59 | C6: 2 | D6: Mar | H6: 2 | I6: 2643 | J6: 48.85 | K6: 817 | L6: 0.014 | M6: 0.0003115 | N6: 0
A7: 04/20/26 | B7: 18:21:59 | C7: 2 | D7: Mar | H7: 3 | I7: 2766 | J7: 23.738 | K7: 1064 | L7: 0.009 | M7: 0.0003909 | N7: 254.877
A8: 04/20/26 | B8: 18:31:01 | C8: 3 | D8: Mar | H8: 1 | I8: 2646 | J8: 47.862 | K8: 819 | L8: 0.014 | M8: 0.0003115 | N8: 0.113
A9: 04/20/26 | B9: 18:31:01 | C9: 3 | D9: Mar | H9: 2 | I9: 2647 | J9: 48.971 | K9: 819 | L9: 0.014 | M9: 0.0003115 | N9: 0
A10: 04/20/26 | B10: 18:31:01 | C10: 3 | D10: Mar | H10: 3 | I10: 2775 | J10: 23.765 | K10: 1069 | L10: 0.009 | M10: 0.0003903 | N10: 252.97
A11: 04/20/26 | B11: 18:40:03 | C11: 4 | D11: Buenos Aires | H11: 1 | I11: 2653 | J11: 47.997 | K11: 822 | L11: 0.014 | M11: 0.0003115 | N11: -0.09
A12: 04/20/26 | B12: 18:40:03 | C12: 4 | D12: Buenos Aires | H12: 2 | I12: 2657 | J12: 49.195 | K12: 822 | L12: 0.014 | M12: 0.0003115 | N12: 0
A13: 04/20/26 | B13: 18:40:03 | C13: 4 | D13: Buenos Aires | H13: 3 | I13: 2785 | J13: 23.623 | K13: 1036 | L13: 0.008 | M13: 0.0003762 | N13: 207.583
... A379: 04/21/26 | B379: 13:07:53 | C379: 126 | D379: Antartida | H379: 3 | I379: 2747 | J379: 24.854 | K379: 968 | L379: 0.008 | M379: 0.0003549 | N379: 139.266

Sheet 18O.wke
A1: Date | B1: Time | C1: Row | D1: Identifier 1 | E1: Identifier 2 | F1: Amount | G1: Comment | H1: Peak Nr | I1: Ampl 28 | J1: Ampl 29 | K1: Ampl 30 | L1: Area 28 | M1: Area 29 | N1: Area 30 | O1: R 18O/16O | P1: d 18O/16O
A2: 04/20/26 | B2: 18:12:58 | C2: 1 | D2: Mar | H2: 4 | I2: 4895 | J2: 5460 | K2: 3337 | L2: 54.405 | M2: 0.611 | N2: 0.112 | O2: 0.0020092 | P2: 1.974
A3: 04/20/26 | B3: 18:12:58 | C3: 1 | D3: Mar | H3: 5 | I3: 5866 | J3: 6445 | K3: 4014 | L3: 109.857 | M3: 1.207 | N3: 0.226 | O3: 0.0020055 | P3: 0.163
A4: 04/20/26 | B4: 18:12:58 | C4: 1 | D4: Mar | H4: 6 | I4: 5854 | J4: 6431 | K4: 4004 | L4: 110.663 | M4: 1.216 | N4: 0.227 | O4: 0.0020052 | P4: 0
A5: 04/20/26 | B5: 18:21:59 | C5: 2 | D5: Mar | H5: 4 | I5: 4923 | J5: 5492 | K5: 3356 | L5: 54.345 | M5: 0.611 | N5: 0.112 | O5: 0.0020092 | P5: 2
A6: 04/20/26 | B6: 18:21:59 | C6: 2 | D6: Mar | H6: 5 | I6: 5875 | J6: 6455 | K6: 4019 | L6: 110.512 | M6: 1.214 | N6: 0.227 | O6: 0.0020053 | P6: 0.07
A7: 04/20/26 | B7: 18:21:59 | C7: 2 | D7: Mar | H7: 6 | I7: 5878 | J7: 6456 | K7: 4021 | L7: 111.247 | M7: 1.222 | N7: 0.228 | O7: 0.0020052 | P7: 0
A8: 04/20/26 | B8: 18:31:01 | C8: 3 | D8: Mar | H8: 4 | I8: 4925 | J8: 5492 | K8: 3357 | L8: 54.318 | M8: 0.61 | N8: 0.112 | O8: 0.002009 | P8: 1.909
A9: 04/20/26 | B9: 18:31:01 | C9: 3 | D9: Mar | H9: 5 | I9: 5850 | J9: 6426 | K9: 4001 | L9: 110.098 | M9: 1.21 | N9: 0.226 | O9: 0.0020055 | P9: 0.14
A10: 04/20/26 | B10: 18:31:01 | C10: 3 | D10: Mar | H10: 6 | I10: 5854 | J10: 6432 | K10: 4004 | L10: 110.722 | M10: 1.216 | N10: 0.227 | O10: 0.0020052 | P10: 0
A11: 04/20/26 | B11: 18:40:03 | C11: 4 | D11: Buenos Aires | H11: 4 | I11: 4941 | J11: 5510 | K11: 3346 | L11: 53.988 | M11: 0.607 | N11: 0.11 | O11: 0.0019959 | P11: -4.65
A12: 04/20/26 | B12: 18:40:03 | C12: 4 | D12: Buenos Aires | H12: 5 | I12: 5854 | J12: 6431 | K12: 4005 | L12: 109.98 | M12: 1.208 | N12: 0.226 | O12: 0.0020054 | P12: 0.097
A13: 04/20/26 | B13: 18:40:03 | C13: 4 | D13: Buenos Aires | H13: 6 | I13: 5852 | J13: 6429 | K13: 4003 | L13: 110.654 | M13: 1.216 | N13: 0.227 | O13: 0.0020052 | P13: 0
... A376: 04/21/26 | B376: 13:07:53 | C376: 126 | D376: Antartida | H376: 6 | I376: 5805 | J376: 6377 | K376: 3970 | L376: 110.216 | M376: 1.211 | N376: 0.226 | O376: 0.0020052 | P376: 0

Sheet Deriva
D2: STD | E2: Buenos Aires | S2: 2H
S3: m | T3: {=+LINEST(D5:D26,C5:C26,TRUE,TRUE)} -> 0.0040196659 | U3: 207.07878 | V3: b
C4: Row | D4: d2H raw | E4: d18O raw | S4: S_m | T4: 0.0087085321 | U4: 0.65196716 | V4: S_b
C5: 4 | D5: 207.583 | E5: -4.65 | S5: R2 | T5: 0.010540424 | U5: 1.5493224 | V5: se_v
C6: 5 | D6: 209.739 | E6: -4.456 | S6: F | T6: 0.21305415 | U6: 20 | V6: df
C7: 6 | D7: 207.528 | E7: -4.593 | S7: SS_reg | T7: 0.51141515 | U7: 48.007997 | V7: SS_resid
C8: 23 | D8: 204.577 | E8: -4.489
C9: 24 | D9: 206.811 | E9: -4.636 | S9: m (CI) | T9: =+$T$3-2.2*$T$4 -> -0.015139105 | U9: =+$T$3+2.2*$T$4 -> 0.023178437
C10: 35 | D10: 207.222 | E10: -4.581
C11: 36 | D11: 205.64 | E11: -4.457
C12: 47 | D12: 208.915 | E12: -4.406
C13: 48 | D13: 206.698 | E13: -4.594
C14: 59 | D14: 207.318 | E14: -4.566
C15: 60 | D15: 207.265 | E15: -4.525
C16: 71 | D16: 206.42 | E16: -4.423
C17: 72 | D17: 206.701 | E17: -4.587
C18: 83 | D18: 208.035 | E18: -4.641 | S18: 18O
C19: 84 | D19: 208.456 | E19: -4.5 | S19: m | T19: {=+LINEST(E5:E26,C5:C26,TRUE,TRUE)} -> 0.0017255332 | U19: -4.6060117 | V19: b
C20: 95 | D20: 206.475 | E20: -4.661 | S20: S_m | T20: 0.00057230786 | U20: 0.042846019 | V20: S_b
C21: 96 | D21: 206.227 | E21: -4.406 | S21: R2 | T21: 0.31249007 | U21: 0.10181846 | V21: se_v
C22: 107 | D22: 207.425 | E22: -4.431 | S22: F | T22: 9.0904888 | U22: 20 | V22: df
C23: 108 | D23: 207.91 | E23: -4.39 | S23: SS_reg | T23: 0.094241095 | U23: 0.20734 | V23: SS_resid
C24: 118 | D24: 207.123 | E24: -4.254
C25: 119 | D25: 211.847 | E25: -4.256 | S25: m (CI) | T25: =+$T$19-2.2*$T$20 -> 0.00046645594 | U25: =+$T$19+2.2*$T$20 -> 0.0029846105
C26: 120 | D26: 205.526 | E26: -4.38
C31: MEAN | D31: =+AVERAGE(D5:D30) -> 207.33823 | E31: =+AVERAGE(E5:E30) -> -4.4946364
C32: SD | D32: =+_xlfn.STDEV.P(D5:D26) -> 1.4850683 | E32: =+_xlfn.STDEV.P(E5:E26) -> 0.11708216

Sheet 2H filtrado
A1: Date | B1: Time | C1: Row | D1: Identifier 1 | E1: Identifier 2 | F1: Amount | G1: Comment | H1: Peak Nr | I1: Ampl 2 | J1: Area 2 | K1: Ampl 3 | L1: Area 3 | M1: R 3H2/2H2 | N1: d 3H2/2H2
A2: 04/20/26 | B2: 18:12:58 | C2: 1 | D2: Mar | H2: 3 | I2: 2766 | J2: 23.81 | K2: 1065 | L2: 0.009 | M2: 0.0003904 | N2: 253.256
A3: 04/20/26 | B3: 18:21:59 | C3: 2 | D3: Mar | H3: 3 | I3: 2766 | J3: 23.738 | K3: 1064 | L3: 0.009 | M3: 0.0003909 | N3: 254.877
A4: 04/20/26 | B4: 18:31:01 | C4: 3 | D4: Mar | H4: 3 | I4: 2775 | J4: 23.765 | K4: 1069 | L4: 0.009 | M4: 0.0003903 | N4: 252.97
A5: 04/20/26 | B5: 18:40:03 | C5: 4 | D5: Buenos Aires | H5: 3 | I5: 2785 | J5: 23.623 | K5: 1036 | L5: 0.008 | M5: 0.0003762 | N5: 207.583
A6: 04/20/26 | B6: 18:49:04 | C6: 5 | D6: Buenos Aires | H6: 3 | I6: 2838 | J6: 24.614 | K6: 1057 | L6: 0.009 | M6: 0.0003768 | N6: 209.739
A7: 04/20/26 | B7: 18:58:05 | C7: 6 | D7: Buenos Aires | H7: 3 | I7: 2896 | J7: 24.906 | K7: 1078 | L7: 0.009 | M7: 0.0003761 | N7: 207.528
A8: 04/20/26 | B8: 19:07:07 | C8: 7 | D8: Mendoza | H8: 3 | I8: 2845 | J8: 24.728 | K8: 1026 | L8: 0.008 | M8: 0.0003636 | N8: 167.182
A9: 04/20/26 | B9: 19:16:09 | C9: 8 | D9: Mendoza | H9: 3 | I9: 2815 | J9: 24.37 | K9: 1012 | L9: 0.008 | M9: 0.0003627 | N9: 164.245
A10: 04/20/26 | B10: 19:25:10 | C10: 9 | D10: Mendoza | H10: 3 | I10: 2775 | J10: 23.885 | K10: 999 | L10: 0.008 | M10: 0.0003633 | N10: 166.371
A11: 04/20/26 | B11: 19:34:12 | C11: 10 | D11: Antartida | H11: 3 | I11: 2788 | J11: 24.301 | K11: 983 | L11: 0.008 | M11: 0.0003556 | N11: 141.551
A12: 04/20/26 | B12: 19:43:13 | C12: 11 | D12: Antartida | H12: 3 | I12: 2853 | J12: 24.763 | K12: 1005 | L12: 0.008 | M12: 0.000354 | N12: 136.439
A13: 04/20/26 | B13: 19:52:15 | C13: 12 | D13: Antartida | H13: 3 | I13: 2779 | J13: 24.277 | K13: 979 | L13: 0.008 | M13: 0.0003545 | N13: 138.195
... A127: 04/21/26 | B127: 13:07:53 | C127: 126 | D127: Antartida | H127: 3 | I127: 2747 | J127: 24.854 | K127: 968 | L127: 0.008 | M127: 0.0003549 | N127: 139.266

Sheet 18O filtrado
A1: Date | B1: Time | C1: Row | D1: Identifier 1 | E1: Identifier 2 | F1: Amount | G1: Comment | H1: Peak Nr | I1: Ampl 28 | J1: Ampl 29 | K1: Ampl 30 | L1: Area 28 | M1: Area 29 | N1: Area 30 | O1: R 18O/16O | P1: d 18O/16O
A2: 04/20/26 | B2: 18:12:58 | C2: 1 | D2: Mar | H2: 4 | I2: 4895 | J2: 5460 | K2: 3337 | L2: 54.405 | M2: 0.611 | N2: 0.112 | O2: 0.0020092 | P2: 1.974
A3: 04/20/26 | B3: 18:21:59 | C3: 2 | D3: Mar | H3: 4 | I3: 4923 | J3: 5492 | K3: 3356 | L3: 54.345 | M3: 0.611 | N3: 0.112 | O3: 0.0020092 | P3: 2
A4: 04/20/26 | B4: 18:31:01 | C4: 3 | D4: Mar | H4: 4 | I4: 4925 | J4: 5492 | K4: 3357 | L4: 54.318 | M4: 0.61 | N4: 0.112 | O4: 0.002009 | P4: 1.909
A5: 04/20/26 | B5: 18:40:03 | C5: 4 | D5: Buenos Aires | H5: 4 | I5: 4941 | J5: 5510 | K5: 3346 | L5: 53.988 | M5: 0.607 | N5: 0.11 | O5: 0.0019959 | P5: -4.65
A6: 04/20/26 | B6: 18:49:04 | C6: 5 | D6: Buenos Aires | H6: 4 | I6: 5059 | J6: 5642 | K6: 3427 | L6: 56.291 | M6: 0.633 | N6: 0.115 | O6: 0.0019963 | P6: -4.456
A7: 04/20/26 | B7: 18:58:05 | C7: 6 | D7: Buenos Aires | H7: 4 | I7: 5124 | J7: 5713 | K7: 3469 | L7: 56.683 | M7: 0.637 | N7: 0.116 | O7: 0.001996 | P7: -4.593
A8: 04/20/26 | B8: 19:07:07 | C8: 7 | D8: Mendoza | H8: 4 | I8: 5051 | J8: 5632 | K8: 3402 | L8: 56.221 | M8: 0.632 | N8: 0.114 | O8: 0.0019849 | P8: -10.119
A9: 04/20/26 | B9: 19:16:09 | C9: 8 | D9: Mendoza | H9: 4 | I9: 4999 | J9: 5574 | K9: 3365 | L9: 55.574 | M9: 0.624 | N9: 0.113 | O9: 0.0019845 | P9: -10.317
A10: 04/20/26 | B10: 19:25:10 | C10: 9 | D10: Mendoza | H10: 4 | I10: 4926 | J10: 5494 | K10: 3316 | L10: 54.508 | M10: 0.612 | N10: 0.111 | O10: 0.0019844 | P10: -10.349
A11: 04/20/26 | B11: 19:34:12 | C11: 10 | D11: Antartida | H11: 4 | I11: 4953 | J11: 5523 | K11: 3331 | L11: 55.406 | M11: 0.623 | N11: 0.112 | O11: 0.0019829 | P11: -11.12
A12: 04/20/26 | B12: 19:43:13 | C12: 11 | D12: Antartida | H12: 4 | I12: 5076 | J12: 5660 | K12: 3412 | L12: 56.697 | M12: 0.637 | N12: 0.115 | O12: 0.0019821 | P12: -11.542
A13: 04/20/26 | B13: 19:52:15 | C13: 12 | D13: Antartida | H13: 4 | I13: 4934 | J13: 5501 | K13: 3318 | L13: 55.225 | M13: 0.62 | N13: 0.112 | O13: 0.0019827 | P13: -11.24
... A125: 04/21/26 | B125: 13:07:53 | C125: 126 | D125: Antartida | H125: 4 | I125: 4961 | J125: 5534 | K125: 3337 | L125: 57.071 | M125: 0.641 | N125: 0.116 | O125: 0.0019825 | P125: -11.341

Sheet 2H proc
A1: Estadistica descriptiva mat de referencia in-house | H1: !COPIAR A MANO LOS VALORES PARA NORMALIZAR
B3: MATERIAL | C3: Mar | D3: Buenos Aires | E3: Mendoza | F3: Antartida | H3: MATERIAL | I3: 2H raw | J3: 2H ref
A4: RAW | B4: MEAN | C4: =+AVERAGEIF('2H filtrado'!D:D,"=Mar",'2H filtrado'!N:N) -> 255.38167 | D4: =+AVERAGEIF('2H filtrado'!D:D,"=Buenos Aires",'2H filtrado'!N:N) -> 207.33823 | E4: =+AVERAGEIF('2H filtrado'!D:D,"=Mendoza",'2H filtrado'!N:N) -> 166.05417 | F4: =+AVERAGEIF('2H filtrado'!D:D,"=Antartida",'2H filtrado'!N:N) -> 138.85283 | H4: Mar | I4: 253.256 | J4: -0.49
B5: SD | C5: {=+STDEV(IF('2H filtrado'!$D:$D=C3,'2H filtrado'!$N:$N))} -> 2.2314304 | D5: {=+STDEV(IF('2H filtrado'!$D:$D=D3,'2H filtrado'!$N:$N))} -> 1.5200158 | E5: {=+STDEV(IF('2H filtrado'!$D:$D=E3,'2H filtrado'!$N:$N))} -> 1.2945225 | F5: {=+STDEV(IF('2H filtrado'!$D:$D=F3,'2H filtrado'!$N:$N))} -> 1.6881739 | H5: Mar | I5: 254.877 | J5: -0.49
B6: N | C6: {=+COUNT(IF('2H filtrado'!$D:$D=C3,'2H filtrado'!$N:$N))} -> 6 | D6: {=+COUNT(IF('2H filtrado'!$D:$D=D3,'2H filtrado'!$N:$N))} -> 22 | E6: {=+COUNT(IF('2H filtrado'!$D:$D=E3,'2H filtrado'!$N:$N))} -> 6 | F6: {=+COUNT(IF('2H filtrado'!$D:$D=F3,'2H filtrado'!$N:$N))} -> 6 | H6: Mar | I6: 252.97 | J6: -0.49
H7: Buenos Aires | I7: 207.583 | J7: -36.92
B8: REFERENCIA | C8: -0.49 | D8: -36.92 | E8: -72.07 | F8: -94.89 | H8: Buenos Aires | I8: 209.739 | J8: -36.92
H9: Buenos Aires | I9: 207.528 | J9: -36.92
A10: NORM | B10: MEAN | C10: =+AVERAGEIF($B$31:$B$400,C3,$D$31:$D$400) -> 0.23596264 | D10: =+AVERAGEIF($B$31:$B$400,D3,$D$31:$D$400) -> -38.750009 | E10: =+AVERAGEIF($B$31:$B$400,E3,$D$31:$D$400) -> -72.250924 | F10: =+AVERAGEIF($B$31:$B$400,F3,$D$31:$D$400) -> -94.324081 | H10: Mendoza | I10: 167.182 | J10: -72.07
B11: SD | C11: {=+STDEV(IF($B$31:$B$400=C3,$D$31:$D$400))} -> 1.8107463 | D11: {=+STDEV(IF($B$31:$B$400=D3,$D$31:$D$400))} -> 1.2334524 | E11: {=+STDEV(IF($B$31:$B$400=E3,$D$31:$D$400))} -> 1.0504705 | F11: {=+STDEV(IF($B$31:$B$400=F3,$D$31:$D$400))} -> 1.3699081 | H11: Mendoza | I11: 164.245 | J11: -72.07
H12: Mendoza | I12: 166.371 | J12: -72.07
H13: Antartida | I13: 141.551 | J13: -94.89
H14: Antartida | I14: 136.439 | J14: -94.89
H15: Antartida | I15: 138.195 | J15: -94.89
H16: Mar | I16: 256.247 | J16: -0.49
H17: Mar | I17: 255.915 | J17: -0.49
H18: Mar | I18: 259.025 | J18: -0.49
H19: Buenos Aires | I19: 207.123 | J19: -36.92
H20: Buenos Aires | I20: 211.847 | J20: -36.92
H21: Buenos Aires | I21: 205.526 | J21: -36.92 | M21: m | N21: =+SLOPE(I4:I27,J4:J27) -> 1.2323263
H22: Mendoza | I22: 167.741 | J22: -72.07 | M22: b | N22: =+INTERCEPT(I4:I27,J4:J27) -> 255.09088
H23: Mendoza | I23: 165.31 | J23: -72.07 | M23: R2 | N23: =+PEARSON(I4:I27,J4:J27)^2 -> 0.99804034
H24: Mendoza | I24: 165.476 | J24: -72.07
H25: Antartida | I25: 139.352 | J25: -94.89
H26: Antartida | I26: 138.314 | J26: -94.89
H27: Antartida | I27: 139.266 | J27: -94.89
A30: =+'2H filtrado'!C1 -> Row | B30: =+'2H filtrado'!D1 -> Identifier 1 | C30: =+'2H filtrado'!N1 -> d 3H2/2H2 | D30: 2H normalizado | F30: IDENTIFICACION | G30: 2H
A31: =+'2H filtrado'!C2 -> 1 | B31: =+'2H filtrado'!D2 -> Mar | C31: =+'2H filtrado'!N2 -> 253.256 | D31: =+(C31-$N$22)/$N$21 -> -1.4889592 | F31: A017 | G31: =+AVERAGEIF($B$31:$B$400,F31,$D$31:$D$400) -> -94.381561
A32: =+'2H filtrado'!C3 -> 2 | B32: =+'2H filtrado'!D3 -> Mar | C32: =+'2H filtrado'!N3 -> 254.877 | D32: =+(C32-$N$22)/$N$21 -> -0.17356092 | F32: A018 | G32: =+AVERAGEIF($B$31:$B$400,F32,$D$31:$D$400) -> -75.484375
A33: =+'2H filtrado'!C4 -> 3 | B33: =+'2H filtrado'!D4 -> Mar | C33: =+'2H filtrado'!N4 -> 252.97 | D33: =+(C33-$N$22)/$N$21 -> -1.7210406 | F33: A019 | G33: =+AVERAGEIF($B$31:$B$400,F33,$D$31:$D$400) -> -35.288853
A34: =+'2H filtrado'!C5 -> 4 | B34: =+'2H filtrado'!D5 -> Buenos Aires | C34: =+'2H filtrado'!N5 -> 207.583 | D34: =+(C34-$N$22)/$N$21 -> -38.551382 | F34: A020 | G34: =+AVERAGEIF($B$31:$B$400,F34,$D$31:$D$400) -> -15.713276
A35: =+'2H filtrado'!C6 -> 5 | B35: =+'2H filtrado'!D6 -> Buenos Aires | C35: =+'2H filtrado'!N6 -> 209.739 | D35: =+(C35-$N$22)/$N$21 -> -36.801846 | F35: A021 | G35: =+AVERAGEIF($B$31:$B$400,F35,$D$31:$D$400) -> -53.553902
A36: =+'2H filtrado'!C7 -> 6 | B36: =+'2H filtrado'!D7 -> Buenos Aires | C36: =+'2H filtrado'!N7 -> 207.528 | D36: =+(C36-$N$22)/$N$21 -> -38.596013 | F36: A022 | G36: =+AVERAGEIF($B$31:$B$400,F36,$D$31:$D$400) -> -76.232959
A37: =+'2H filtrado'!C8 -> 7 | B37: =+'2H filtrado'!D8 -> Mendoza | C37: =+'2H filtrado'!N8 -> 167.182 | D37: =+(C37-$N$22)/$N$21 -> -71.335717 | F37: A023 | G37: =+AVERAGEIF($B$31:$B$400,F37,$D$31:$D$400) -> -110.41019
A38: =+'2H filtrado'!C9 -> 8 | B38: =+'2H filtrado'!D9 -> Mendoza | C38: =+'2H filtrado'!N9 -> 164.245 | D38: =+(C38-$N$22)/$N$21 -> -73.719015 | F38: A024 | G38: =+AVERAGEIF($B$31:$B$400,F38,$D$31:$D$400) -> -55.503872
A39: =+'2H filtrado'!C10 -> 9 | B39: =+'2H filtrado'!D10 -> Mendoza | C39: =+'2H filtrado'!N10 -> 166.371 | D39: =+(C39-$N$22)/$N$21 -> -71.993822 | F39: A025 | G39: =+AVERAGEIF($B$31:$B$400,F39,$D$31:$D$400) -> -20.900619
A40: =+'2H filtrado'!C11 -> 10 | B40: =+'2H filtrado'!D11 -> Antartida | C40: =+'2H filtrado'!N11 -> 141.551 | D40: =+(C40-$N$22)/$N$21 -> -92.134591 | F40: A026 | G40: =+AVERAGEIF($B$31:$B$400,F40,$D$31:$D$400) -> -31.585289
A41: =+'2H filtrado'!C12 -> 11 | B41: =+'2H filtrado'!D12 -> Antartida | C41: =+'2H filtrado'!N12 -> 136.439 | D41: =+(C41-$N$22)/$N$21 -> -96.282843 | F41: A027 | G41: =+AVERAGEIF($B$31:$B$400,F41,$D$31:$D$400) -> -17.342309
A42: =+'2H filtrado'!C13 -> 12 | B42: =+'2H filtrado'!D13 -> Antartida | C42: =+'2H filtrado'!N13 -> 138.195 | D42: =+(C42-$N$22)/$N$21 -> -94.857896 | F42: A028 | G42: =+AVERAGEIF($B$31:$B$400,F42,$D$31:$D$400) -> -28.381592
... A71: =+'2H filtrado'!C42 -> 41 | B71: =+'2H filtrado'!D42 -> A029 | C71: =+'2H filtrado'!N42 -> 242.331 | D71: =+(C71-$N$22)/$N$21 -> -10.354306 | F71: A057 | G71: =+AVERAGEIF($B$31:$B$400,F71,$D$31:$D$400) -> -14.848651
...

Sheet 18O proc
A1: Estadistica descriptiva mat de referencia in-house | H1: !COPIAR A MANO LOS VALORES PARA NORMALIZAR
B3: MATERIAL | C3: Mar | D3: Buenos Aires | E3: Mendoza | F3: Antartida | H3: MATERIAL | I3: 2H raw | J3: 2H ref
A4: RAW | B4: MEAN | C4: =+AVERAGEIF('18O filtrado'!D:D,"=Mar",'18O filtrado'!P:P) -> 2.2013333 | D4: =+AVERAGEIF('18O filtrado'!D:D,"=Buenos Aires",'18O filtrado'!P:P) -> -4.4946364 | E4: =+AVERAGEIF('18O filtrado'!D:D,"=Mendoza",'18O filtrado'!P:P) -> -10.107167 | F4: =+AVERAGEIF('18O filtrado'!D:D,"=Antartida",'18O filtrado'!P:P) -> -11.32 | H4: Mar | I4: 1.974 | J4: -0.027
B5: SD | C5: {=+STDEV(IF('18O filtrado'!$D:$D=C3,'18O filtrado'!$P:$P))} -> 0.26889601 | D5: {=+STDEV(IF('18O filtrado'!$D:$D=D3,'18O filtrado'!$P:$P))} -> 0.11983741 | E5: {=+STDEV(IF('18O filtrado'!$D:$D=E3,'18O filtrado'!$P:$P))} -> 0.25607531 | F5: {=+STDEV(IF('18O filtrado'!$D:$D=F3,'18O filtrado'!$P:$P))} -> 0.156863 | H5: Mar | I5: 2 | J5: -0.027
B6: N | C6: {=+COUNT(IF('18O filtrado'!$D:$D=C3,'18O filtrado'!$P:$P))} -> 6 | D6: {=+COUNT(IF('18O filtrado'!$D:$D=D3,'18O filtrado'!$P:$P))} -> 22 | E6: {=+COUNT(IF('18O filtrado'!$D:$D=E3,'18O filtrado'!$P:$P))} -> 6 | F6: {=+COUNT(IF('18O filtrado'!$D:$D=F3,'18O filtrado'!$P:$P))} -> 6 | H6: Mar | I6: 1.909 | J6: -0.027
H7: Buenos Aires | I7: -4.65 | J7: -5.442
B8: REFERENCIA | C8: -0.027 | D8: -5.442 | E8: -11.362 | F8: -12.78 | H8: Buenos Aires | I8: -4.456 | J8: -5.442
H9: Buenos Aires | I9: -4.593 | J9: -5.442
A10: NORM | B10: MEAN | C10: =+AVERAGEIF($B$31:$B$400,C3,$D$31:$D$400) -> 0.29394218 | D10: =+AVERAGEIF($B$31:$B$400,D3,$D$31:$D$400) -> -6.0563454 | E10: =+AVERAGEIF($B$31:$B$400,E3,$D$31:$D$400) -> -11.379127 | F10: =+AVERAGEIF($B$31:$B$400,F3,$D$31:$D$400) -> -12.529347 | H10: Mendoza | I10: -10.119 | J10: -11.362
B11: SD | C11: {=+STDEV(IF($B$31:$B$400=C3,$D$31:$D$400))} -> 0.25501415 | D11: {=+STDEV(IF($B$31:$B$400=D3,$D$31:$D$400))} -> 0.11365075 | E11: {=+STDEV(IF($B$31:$B$400=E3,$D$31:$D$400))} -> 0.24285533 | F11: {=+STDEV(IF($B$31:$B$400=F3,$D$31:$D$400))} -> 0.14876488 | H11: Mendoza | I11: -10.317 | J11: -11.362
H12: Mendoza | I12: -10.349 | J12: -11.362
H13: Antartida | I13: -11.12 | J13: -12.78
H14: Antartida | I14: -11.542 | J14: -12.78
H15: Antartida | I15: -11.24 | J15: -12.78
H16: Mar | I16: 2.523 | J16: -0.027
H17: Mar | I17: 2.383 | J17: -0.027
H18: Mar | I18: 2.419 | J18: -0.027
H19: Buenos Aires | I19: -4.254 | J19: -5.442
H20: Buenos Aires | I20: -4.256 | J20: -5.442
H21: Buenos Aires | I21: -4.38 | J21: -5.442 | M21: m | N21: =+SLOPE(I4:I27,J4:J27) -> 1.0544357
H22: Mendoza | I22: -9.931 | J22: -11.362 | M22: b | N22: =+INTERCEPT(I4:I27,J4:J27) -> 1.8913902
H23: Mendoza | I23: -10.24 | J23: -11.362 | M23: R2 | N23: =+PEARSON(I4:I27,J4:J27)^2 -> 0.9940433
H24: Mendoza | I24: -9.687 | J24: -11.362
H25: Antartida | I25: -11.224 | J25: -12.78
H26: Antartida | I26: -11.453 | J26: -12.78
H27: Antartida | I27: -11.341 | J27: -12.78
A30: =+'18O filtrado'!C1 -> Row | B30: =+'18O filtrado'!D1 -> Identifier 1 | C30: =+'18O filtrado'!P1 -> d 18O/16O | D30: 18O normalizado | F30: IDENTIFICACION | G30: 18O
A31: =+'18O filtrado'!C2 -> 1 | B31: =+'18O filtrado'!D2 -> Mar | C31: =+'18O filtrado'!P2 -> 1.974 | D31: =+(C31-$N$22)/$N$21 -> 0.078345019 | F31: A017 | G31: =+AVERAGEIF($B$31:$B$400,F31,$D$31:$D$400) -> -13.945744
A32: =+'18O filtrado'!C3 -> 2 | B32: =+'18O filtrado'!D3 -> Mar | C32: =+'18O filtrado'!P3 -> 2 | D32: =+(C32-$N$22)/$N$21 -> 0.10300276 | F32: A018 | G32: =+AVERAGEIF($B$31:$B$400,F32,$D$31:$D$400) -> -12.016751
A33: =+'18O filtrado'!C4 -> 3 | B33: =+'18O filtrado'!D4 -> Mar | C33: =+'18O filtrado'!P4 -> 1.909 | D33: =+(C33-$N$22)/$N$21 -> 0.01670067 | F33: A019 | G33: =+AVERAGEIF($B$31:$B$400,F33,$D$31:$D$400) -> -6.3279254
A34: =+'18O filtrado'!C5 -> 4 | B34: =+'18O filtrado'!D5 -> Buenos Aires | C34: =+'18O filtrado'!P5 -> -4.65 | D34: =+(C34-$N$22)/$N$21 -> -6.2036884 | F34: A020 | G34: =+AVERAGEIF($B$31:$B$400,F34,$D$31:$D$400) -> -3.4809049
A35: =+'18O filtrado'!C6 -> 5 | B35: =+'18O filtrado'!D6 -> Buenos Aires | C35: =+'18O filtrado'!P6 -> -4.456 | D35: =+(C35-$N$22)/$N$21 -> -6.0197037 | F35: A021 | G35: =+AVERAGEIF($B$31:$B$400,F35,$D$31:$D$400) -> -7.6172407
A36: =+'18O filtrado'!C7 -> 6 | B36: =+'18O filtrado'!D7 -> Buenos Aires | C36: =+'18O filtrado'!P7 -> -4.593 | D36: =+(C36-$N$22)/$N$21 -> -6.149631 | F36: A022 | G36: =+AVERAGEIF($B$31:$B$400,F36,$D$31:$D$400) -> -11.021906
A37: =+'18O filtrado'!C8 -> 7 | B37: =+'18O filtrado'!D8 -> Mendoza | C37: =+'18O filtrado'!P8 -> -10.119 | D37: =+(C37-$N$22)/$N$21 -> -11.390349 | F37: A023 | G37: =+AVERAGEIF($B$31:$B$400,F37,$D$31:$D$400) -> -15.260666
A38: =+'18O filtrado'!C9 -> 8 | B38: =+'18O filtrado'!D9 -> Mendoza | C38: =+'18O filtrado'!P9 -> -10.317 | D38: =+(C38-$N$22)/$N$21 -> -11.578127 | F38: A024 | G38: =+AVERAGEIF($B$31:$B$400,F38,$D$31:$D$400) -> -8.9198332
A39: =+'18O filtrado'!C10 -> 9 | B39: =+'18O filtrado'!D10 -> Mendoza | C39: =+'18O filtrado'!P10 -> -10.349 | D39: =+(C39-$N$22)/$N$21 -> -11.608475 | F39: A025 | G39: =+AVERAGEIF($B$31:$B$400,F39,$D$31:$D$400) -> -4.0807518
A40: =+'18O filtrado'!C11 -> 10 | B40: =+'18O filtrado'!D11 -> Antartida | C40: =+'18O filtrado'!P11 -> -11.12 | D40: =+(C40-$N$22)/$N$21 -> -12.339672 | F40: A026 | G40: =+AVERAGEIF($B$31:$B$400,F40,$D$31:$D$400) -> -6.3198643
A41: =+'18O filtrado'!C12 -> 11 | B41: =+'18O filtrado'!D12 -> Antartida | C41: =+'18O filtrado'!P12 -> -11.542 | D41: =+(C41-$N$22)/$N$21 -> -12.739886 | F41: A027 | G41: =+AVERAGEIF($B$31:$B$400,F41,$D$31:$D$400) -> -3.9465568
A42: =+'18O filtrado'!C13 -> 12 | B42: =+'18O filtrado'!D13 -> Antartida | C42: =+'18O filtrado'!P13 -> -11.24 | D42: =+(C42-$N$22)/$N$21 -> -12.453477 | F42: A028 | G42: =+AVERAGEIF($B$31:$B$400,F42,$D$31:$D$400) -> -5.7845068
... A71: =+'18O filtrado'!C42 -> 41 | B71: =+'18O filtrado'!D42 -> A029 | C71: =+'18O filtrado'!P42 -> -2.103 | D71: =+(C71-$N$22)/$N$21 -> -3.7881783 | F71: A057 | G71: =+AVERAGEIF($B$31:$B$400,F71,$D$31:$D$400) -> -4.3837575
...

Sheet 2H VS 18O
A1: =+'2H proc'!F30 -> IDENTIFICACION | B1: =+'2H proc'!G30 -> 2H | C1: =+'18O proc'!F30 -> IDENTIFICACION | D1: =+'18O proc'!G30 -> 18O
A2: =+'2H proc'!F31 -> A017 | B2: =+'2H proc'!G31 -> -94.381561 | C2: =+'18O proc'!F31 -> A017 | D2: =+'18O proc'!G31 -> -13.945744
A3: =+'2H proc'!F32 -> A018 | B3: =+'2H proc'!G32 -> -75.484375 | C3: =+'18O proc'!F32 -> A018 | D3: =+'18O proc'!G32 -> -12.016751
A4: =+'2H proc'!F33 -> A019 | B4: =+'2H proc'!G33 -> -35.288853 | C4: =+'18O proc'!F33 -> A019 | D4: =+'18O proc'!G33 -> -6.3279254
A5: =+'2H proc'!F34 -> A020 | B5: =+'2H proc'!G34 -> -15.713276 | C5: =+'18O proc'!F34 -> A020 | D5: =+'18O proc'!G34 -> -3.4809049
A6: =+'2H proc'!F35 -> A021 | B6: =+'2H proc'!G35 -> -53.553902 | C6: =+'18O proc'!F35 -> A021 | D6: =+'18O proc'!G35 -> -7.6172407
A7: =+'2H proc'!F36 -> A022 | B7: =+'2H proc'!G36 -> -76.232959 | C7: =+'18O proc'!F36 -> A022 | D7: =+'18O proc'!G36 -> -11.021906
A8: =+'2H proc'!F37 -> A023 | B8: =+'2H proc'!G37 -> -110.41019 | C8: =+'18O proc'!F37 -> A023 | D8: =+'18O proc'!G37 -> -15.260666
A9: =+'2H proc'!F38 -> A024 | B9: =+'2H proc'!G38 -> -55.503872 | C9: =+'18O proc'!F38 -> A024 | D9: =+'18O proc'!G38 -> -8.9198332
A10: =+'2H proc'!F39 -> A025 | B10: =+'2H proc'!G39 -> -20.900619 | C10: =+'18O proc'!F39 -> A025 | D10: =+'18O proc'!G39 -> -4.0807518
A11: =+'2H proc'!F40 -> A026 | B11: =+'2H proc'!G40 -> -31.585289 | C11: =+'18O proc'!F40 -> A026 | D11: =+'18O proc'!G40 -> -6.3198643
A12: =+'2H proc'!F41 -> A027 | B12: =+'2H proc'!G41 -> -17.342309 | C12: =+'18O proc'!F41 -> A027 | D12: =+'18O proc'!G41 -> -3.9465568
... A45: =+'2H proc'!F74 -> A016 | B45: =+'2H proc'!G74 -> -1.4804388 | C45: =+'18O proc'!F74 -> A016 | D45: =+'18O proc'!G74 -> -2.296385

Sheet para informe
A1: ID | B1: Nombre | C1: 2H | D1: 18O | H1: Muestra | I1: δ2H (‰)a | J1: uc (1σ)b | K1: δ18O (‰)a | L1: uc (1σ)b | O1: fuente | P1: SEGOE UI | Q1: 10 pts | R1: se ve bien el simbolo de partpermille | S1: para datos
A2: A017 | B2: LP-May-19 | C2: -94.381561 | D2: -13.945744 | H2: =+B2 -> LP-May-19 | I2: =+C2 -> -94.381561 | J2: 1.4 | K2: =+D2 -> -13.945744 | L2: 0.26 | P2: Cambria | Q2: 11 pts | R2: para texto
A3: A018 | B3: LP-Jun-19 | C3: -75.484375 | D3: -12.016751 | H3: =+B3 -> LP-Jun-19 | I3: =+C3 -> -75.484375 | J3: 1.4 | K3: =+D3 -> -12.016751 | L3: 0.26
A4: A019 | B4: LP-Sep-19 | C4: -35.288853 | D4: -6.3279254 | H4: =+B4 -> LP-Sep-19 | I4: =+C4 -> -35.288853 | J4: 1.4 | K4: =+D4 -> -6.3279254 | L4: 0.26
A5: A020 | B5: LP-Nov-19 | C5: -15.713276 | D5: -3.4809049 | H5: =+B5 -> LP-Nov-19 | I5: =+C5 -> -15.713276 | J5: 1.4 | K5: =+D5 -> -3.4809049 | L5: 0.26
A6: A021 | B6: LP-Dic-19 | C6: -53.553902 | D6: -7.6172407 | H6: =+B6 -> LP-Dic-19 | I6: =+C6 -> -53.553902 | J6: 1.4 | K6: =+D6 -> -7.6172407 | L6: 0.26
A7: A022 | B7: LP-May-20 | C7: -76.232959 | D7: -11.021906 | H7: =+B7 -> LP-May-20 | I7: =+C7 -> -76.232959 | J7: 1.4 | K7: =+D7 -> -11.021906 | L7: 0.26 | O7: * (a) Valores reportados en la escala VSMOW2-SLAP2.
A8: A023 | B8: LP-Jun-20 | C8: -110.41019 | D8: -15.260666 | H8: =+B8 -> LP-Jun-20 | I8: =+C8 -> -110.41019 | J8: 1.4 | K8: =+D8 -> -15.260666 | L8: 0.26 | O8: * (b) Incertidumbre estándar combinada calculada mediante el método de Kragten.
A9: A024 | B9: LP-Jul-20 | C9: -55.503872 | D9: -8.9198332 | H9: =+B9 -> LP-Jul-20 | I9: =+C9 -> -55.503872 | J9: 1.4 | K9: =+D9 -> -8.9198332 | L9: 0.26
A10: A025 | B10: LP-Nov-20 | C10: -20.900619 | D10: -4.0807518 | H10: =+B10 -> LP-Nov-20 | I10: =+C10 -> -20.900619 | J10: 1.4 | K10: =+D10 -> -4.0807518 | L10: 0.26
A11: A026 | B11: LP-Dic-20 | C11: -31.585289 | D11: -6.3198643 | H11: =+B11 -> LP-Dic-20 | I11: =+C11 -> -31.585289 | J11: 1.4 | K11: =+D11 -> -6.3198643 | L11: 0.26
A12: A027 | B12: LP-Nov-21 | C12: -17.342309 | D12: -3.9465568 | H12: =+B12 -> LP-Nov-21 | I12: =+C12 -> -17.342309 | J12: 1.4 | K12: =+D12 -> -3.9465568 | L12: 0.26
A13: A028 | B13: LP-Mar-23 | C13: -28.381592 | D13: -5.7845068 | H13: =+B13 -> LP-Mar-23 | I13: =+C13 -> -28.381592 | J13: 1.4 | K13: =+D13 -> -5.7845068 | L13: 0.26
A14: A029 | B14: LP-Abr-23 | C14: -9.8718848 | D14: -3.8403389 | H14: =+B14 -> LP-Abr-23 | I14: =+C14 -> -9.8718848 | J14: 1.4 | K14: =+D14 -> -3.8403389 | L14: 0.26
A15: A030 | B15: LP-May-23 | C15: -32.53025 | D15: -5.8067936 | H15: =+B15 -> LP-May-23 | I15: =+C15 -> -32.53025 | J15: 1.4 | K15: =+D15 -> -5.8067936 | L15: 0.26
A16: A031 | B16: LP-Jul-23 | C16: -13.435064 | D16: -4.2656849 | H16: =+B16 -> LP-Jul-23 | I16: =+C16 -> -13.435064 | J16: 1.4 | K16: =+D16 -> -4.2656849 | L16: 0.26
A17: A032 | B17: LP-Ago-23 | C17: -114.93902 | D17: -15.423786 | H17: =+B17 -> LP-Ago-23 | I17: =+C17 -> -114.93902 | J17: 1.4 | K17: =+D17 -> -15.423786 | L17: 0.26
A18: A033 | B18: LP-Oct-23 | C18: -6.7189051 | D18: -3.2523466 | H18: =+B18 -> LP-Oct-23 | I18: =+C18 -> -6.7189051 | J18: 1.4 | K18: =+D18 -> -3.2523466 | L18: 0.26
A19: A034 | B19: LP-Nov-23 | C19: -16.660265 | D19: -2.0289434 | H19: =+B19 -> LP-Nov-23 | I19: =+C19 -> -16.660265 | J19: 1.4 | K19: =+D19 -> -2.0289434 | L19: 0.26
A20: A035 | B20: LP-Dic-23 | C20: -23.825981 | D20: -3.3049814 | H20: =+B20 -> LP-Dic-23 | I20: =+C20 -> -23.825981 | J20: 1.4 | K20: =+D20 -> -3.3049814 | L20: 0.26
... A42: A057 | B42: LP-Ene-26 | C42: -14.848651 | D42: -4.3837575 | H42: =+B42 -> LP-Ene-26 | I42: =+C42 -> -14.848651 | J42: 1.4 | K42: =+D42 -> -4.3837575 | L42: 0.26

Sheet incertidumbre kragten 2H
A1: DEFINICION DE VARIABLES | E1: MATRIZ DE PERTURBACION
A3: DESCRIPCION | B3: SIMBOLO | C3: VALOR NOMINAL | D3: INCERT ESTANDAR | E3: CASO BASE | F3: PERT mar_a | G3: PERT mar_m | H3: PERT bsas_a | I3: PERT bsas_m | J3: PERT mdza_a | K3: PERT mdza_m | L3: PERT antartida_a | M3: PERT antartida_m | N3: PERT muestra
A4: asignado MAR | B4: mar_a | C4: -0.49 | D4: 1.34 | E4: =$C4 -> -0.49 | F4: =$C4+$D4 -> 0.85 | G4: =$C4 -> -0.49 | H4: =$C4 -> -0.49 | I4: =$C4 -> -0.49 | J4: =$C4 -> -0.49 | K4: =$C4 -> -0.49 | L4: =$C4 -> -0.49 | M4: =$C4 -> -0.49 | N4: =$C4 -> -0.49
A5: medido MAR | B5: mar_m | C5: =+'2H proc'!C4 -> 255.38167 | D5: 1.34 | E5: =C5 -> 255.38167 | F5: =$C5 -> 255.38167 | G5: =$C5+$D5 -> 256.72167 | H5: =$C5 -> 255.38167 | I5: =$C5 -> 255.38167 | J5: =$C5 -> 255.38167 | K5: =$C5 -> 255.38167 | L5: =$C5 -> 255.38167 | M5: =$C5 -> 255.38167 | N5: =$C5 -> 255.38167
A6: asignado BSAS | B6: bsas_a | C6: -36.92 | D6: 1.34 | E6: =C6 -> -36.92 | F6: =$C6 -> -36.92 | G6: =$C6 -> -36.92 | H6: =$C6+$D6 -> -35.58 | I6: =$C6 -> -36.92 | J6: =$C6 -> -36.92 | K6: =$C6 -> -36.92 | L6: =$C6 -> -36.92 | M6: =$C6 -> -36.92 | N6: =$C6 -> -36.92
A7: medido BSAS | B7: bsas_m | C7: =+'2H proc'!D4 -> 207.33823 | D7: 1.34 | E7: =C7 -> 207.33823 | F7: =$C7 -> 207.33823 | G7: =$C7 -> 207.33823 | H7: =$C7 -> 207.33823 | I7: =$C7+$D7 -> 208.67823 | J7: =$C7 -> 207.33823 | K7: =$C7 -> 207.33823 | L7: =$C7 -> 207.33823 | M7: =$C7 -> 207.33823 | N7: =$C7 -> 207.33823
A8: asignado MDZA | B8: mdza_a | C8: -72.07 | D8: 1.34 | E8: =C8 -> -72.07 | F8: =$C8 -> -72.07 | G8: =$C8 -> -72.07 | H8: =$C8 -> -72.07 | I8: =$C8 -> -72.07 | J8: =$C8+$D8 -> -70.73 | K8: =$C8 -> -72.07 | L8: =$C8 -> -72.07 | M8: =$C8 -> -72.07 | N8: =$C8 -> -72.07
A9: medido MDZA | B9: mdza_m | C9: =+'2H proc'!E4 -> 166.05417 | D9: 1.34 | E9: =C9 -> 166.05417 | F9: =$C9 -> 166.05417 | G9: =$C9 -> 166.05417 | H9: =$C9 -> 166.05417 | I9: =$C9 -> 166.05417 | J9: =$C9 -> 166.05417 | K9: =$C9+$D9 -> 167.39417 | L9: =$C9 -> 166.05417 | M9: =$C9 -> 166.05417 | N9: =$C9 -> 166.05417
A10: asignado ANTARTIDA | B10: antartida_a | C10: -94.89 | D10: 1.34 | E10: =C10 -> -94.89 | F10: =$C10 -> -94.89 | G10: =$C10 -> -94.89 | H10: =$C10 -> -94.89 | I10: =$C10 -> -94.89 | J10: =$C10 -> -94.89 | K10: =$C10 -> -94.89 | L10: =$C10+$D10 -> -93.55 | M10: =$C10 -> -94.89 | N10: =$C10 -> -94.89
A11: medido ANTARTIDA | B11: antartida_m | C11: =+'2H proc'!F4 -> 138.85283 | D11: 1.34 | E11: =C11 -> 138.85283 | F11: =$C11 -> 138.85283 | G11: =$C11 -> 138.85283 | H11: =$C11 -> 138.85283 | I11: =$C11 -> 138.85283 | J11: =$C11 -> 138.85283 | K11: =$C11 -> 138.85283 | L11: =$C11 -> 138.85283 | M11: =$C11+$D11 -> 140.19283 | N11: =$C11 -> 138.85283
A12: medido MUESTRA | B12: muestra | C12: 204 | D12: 1.34 | E12: =C12 -> 204 | F12: =$C12 -> 204 | G12: =$C12 -> 204 | H12: =$C12 -> 204 | I12: =$C12 -> 204 | J12: =$C12 -> 204 | K12: =$C12 -> 204 | L12: =$C12 -> 204 | M12: =$C12 -> 204 | N12: =$C12+$D12 -> 205.34
C14: CALCULOS
D15: Pendiente | E15: =SLOPE(_xlfn.VSTACK(E5,E7,E9,E11),_xlfn.VSTACK(E4, E6,E8,E10)) -> 1.2298734 | F15: =SLOPE(_xlfn.VSTACK(F5,F7,F9,F11),_xlfn.VSTACK(F4, F6,F8,F10)) -> 1.2140101 | G15: =SLOPE(_xlfn.VSTACK(G5,G7,G9,G11),_xlfn.VSTACK(G4, G6,G8,G10)) -> 1.2431177 | H15: =SLOPE(_xlfn.VSTACK(H5,H7,H9,H11),_xlfn.VSTACK(H4, H6,H8,H10)) -> 1.2245059 | I15: =SLOPE(_xlfn.VSTACK(I5,I7,I9,I11),_xlfn.VSTACK(I4, I6,I8,I10)) -> 1.2335828 | J15: =SLOPE(_xlfn.VSTACK(J5,J7,J9,J11),_xlfn.VSTACK(J4, J6,J8,J10)) -> 1.2363582 | K15: =SLOPE(_xlfn.VSTACK(K5,K7,K9,K11),_xlfn.VSTACK(K4, K6,K8,K10)) -> 1.2243829 | L15: =SLOPE(_xlfn.VSTACK(L5,L7,L9,L11),_xlfn.VSTACK(L4, L6,L8,L10)) -> 1.2441849 | ... N15: =SLOPE(_xlfn.VSTACK(N5,N7,N9,N11),_xlfn.VSTACK(N4, N6,N8,N10)) -> 1.2298734
D16: Interseccion | E16: =+INTERCEPT(_xlfn.VSTACK(E5,E7,E9,E11),_xlfn.VSTACK(E4, E6,E8,E10)) -> 254.74403 | F16: =+INTERCEPT(_xlfn.VSTACK(F5,F7,F9,F11),_xlfn.VSTACK(F4, F6,F8,F10)) -> 253.52684 | G16: =+INTERCEPT(_xlfn.VSTACK(G5,G7,G9,G11),_xlfn.VSTACK(G4, G6,G8,G10)) -> 255.75571 | H16: =+INTERCEPT(_xlfn.VSTACK(H5,H7,H9,H11),_xlfn.VSTACK(H4, H6,H8,H10)) -> 254.05958 | I16: =+INTERCEPT(_xlfn.VSTACK(I5,I7,I9,I11),_xlfn.VSTACK(I4, I6,I8,I10)) -> 255.26855 | J16: =+INTERCEPT(_xlfn.VSTACK(J5,J7,J9,J11),_xlfn.VSTACK(J4, J6,J8,J10)) -> 254.66117 | K16: =+INTERCEPT(_xlfn.VSTACK(K5,K7,K9,K11),_xlfn.VSTACK(K4, K6,K8,K10)) -> 254.79851 | L16: =+INTERCEPT(_xlfn.VSTACK(L5,L7,L9,L11),_xlfn.VSTACK(L4, L6,L8,L10)) -> 255.05844 | ... N16: =+INTERCEPT(_xlfn.VSTACK(N5,N7,N9,N11),_xlfn.VSTACK(N4, N6,N8,N10)) -> 254.74403
D17: Resultado perturbado | E17: =+(E12-E16)/E15 -> -41.259556 | F17: =+(F12-F16)/F15 -> -40.79607 | G17: =+(G12-G16)/G15 -> -41.633801 | H17: =+(H12-H16)/H15 -> -40.881454 | I17: =+(I12-I16)/I15 -> -41.56069 | J17: =+(J12-J16)/J15 -> -40.97613 | K17: =+(K12-K16)/K15 -> -41.48907 | L17: =+(L12-L16)/L15 -> -41.037662 | ... N17: =+(N12-N16)/N15 -> -40.170013
E19: DIF caso base | F19: =F17-$E$17 -> 0.46348567 | G19: =G17-$E$17 -> -0.37424468 | H19: =H17-$E$17 -> 0.37810193 | I19: =I17-$E$17 -> -0.30113441 | J19: =J17-$E$17 -> 0.28342586 | K19: =K17-$E$17 -> -0.22951355 | L19: =L17-$E$17 -> 0.22189445 | M19: =M17-$E$17 -> -0.182437 | N19: =N17-$E$17 -> 1.089543
E20: VAR est | F20: =POWER(F19,2) -> 0.21481897 | G20: =POWER(G19,2) -> 0.14005908 | H20: =POWER(H19,2) -> 0.14296107 | I20: =POWER(I19,2) -> 0.090681932 | J20: =POWER(J19,2) -> 0.080330218 | K20: =POWER(K19,2) -> 0.05267647 | L20: =POWER(L19,2) -> 0.049237149 | M20: =POWER(M19,2) -> 0.03328326 | N20: =POWER(N19,2) -> 1.187104
E22: VAR COMB | F22: =SUM(F20:N20) -> 1.9911521
E23: u_c | F23: =SQRT(F22) -> 1.4110819

Sheet incertidumbre kragten 18O
A1: DEFINICION DE VARIABLES | E1: MATRIZ DE PERTURBACION
A3: DESCRIPCION | B3: SIMBOLO | C3: VALOR NOMINAL | D3: INCERT ESTANDAR | E3: CASO BASE | F3: PERT mar_a | G3: PERT mar_m | H3: PERT bsas_a | I3: PERT bsas_m | J3: PERT mdza_a | K3: PERT mdza_m | L3: PERT antartida_a | M3: PERT antartida_m | N3: PERT muestra
A4: asignado MAR | B4: mar_a | C4: -0.027 | D4: 0.22 | E4: =$C4 -> -0.027 | F4: =$C4+$D4 -> 0.193 | G4: =$C4 -> -0.027 | H4: =$C4 -> -0.027 | I4: =$C4 -> -0.027 | J4: =$C4 -> -0.027 | K4: =$C4 -> -0.027 | L4: =$C4 -> -0.027 | M4: =$C4 -> -0.027 | N4: =$C4 -> -0.027
A5: medido MAR | B5: mar_m | C5: =+'18O proc'!C4 -> 2.2013333 | D5: 0.22 | E5: =C5 -> 2.2013333 | F5: =$C5 -> 2.2013333 | G5: =$C5+$D5 -> 2.4213333 | H5: =$C5 -> 2.2013333 | I5: =$C5 -> 2.2013333 | J5: =$C5 -> 2.2013333 | K5: =$C5 -> 2.2013333 | L5: =$C5 -> 2.2013333 | M5: =$C5 -> 2.2013333 | N5: =$C5 -> 2.2013333
A6: asignado BSAS | B6: bsas_a | C6: -5.442 | D6: 0.22 | E6: =C6 -> -5.442 | F6: =$C6 -> -5.442 | G6: =$C6 -> -5.442 | H6: =$C6+$D6 -> -5.222 | I6: =$C6 -> -5.442 | J6: =$C6 -> -5.442 | K6: =$C6 -> -5.442 | L6: =$C6 -> -5.442 | M6: =$C6 -> -5.442 | N6: =$C6 -> -5.442
A7: medido BSAS | B7: bsas_m | C7: =+'18O proc'!D4 -> -4.4946364 | D7: 0.22 | E7: =C7 -> -4.4946364 | F7: =$C7 -> -4.4946364 | G7: =$C7 -> -4.4946364 | H7: =$C7 -> -4.4946364 | I7: =$C7+$D7 -> -4.2746364 | J7: =$C7 -> -4.4946364 | K7: =$C7 -> -4.4946364 | L7: =$C7 -> -4.4946364 | M7: =$C7 -> -4.4946364 | N7: =$C7 -> -4.4946364
A8: asignado MDZA | B8: mdza_a | C8: -11.362 | D8: 0.22 | E8: =C8 -> -11.362 | F8: =$C8 -> -11.362 | G8: =$C8 -> -11.362 | H8: =$C8 -> -11.362 | I8: =$C8 -> -11.362 | J8: =$C8+$D8 -> -11.142 | K8: =$C8 -> -11.362 | L8: =$C8 -> -11.362 | M8: =$C8 -> -11.362 | N8: =$C8 -> -11.362
A9: medido MDZA | B9: mdza_m | C9: =+'18O proc'!E4 -> -10.107167 | D9: 0.22 | E9: =C9 -> -10.107167 | F9: =$C9 -> -10.107167 | G9: =$C9 -> -10.107167 | H9: =$C9 -> -10.107167 | I9: =$C9 -> -10.107167 | J9: =$C9 -> -10.107167 | K9: =$C9+$D9 -> -9.8871667 | L9: =$C9 -> -10.107167 | M9: =$C9 -> -10.107167 | N9: =$C9 -> -10.107167
A10: asignado ANTARTIDA | B10: antartida_a | C10: -12.78 | D10: 0.22 | E10: =C10 -> -12.78 | F10: =$C10 -> -12.78 | G10: =$C10 -> -12.78 | H10: =$C10 -> -12.78 | I10: =$C10 -> -12.78 | J10: =$C10 -> -12.78 | K10: =$C10 -> -12.78 | L10: =$C10+$D10 -> -12.56 | M10: =$C10 -> -12.78 | N10: =$C10 -> -12.78
A11: medido ANTARTIDA | B11: antartida_m | C11: =+'18O proc'!F4 -> -11.32 | D11: 0.22 | E11: =C11 -> -11.32 | F11: =$C11 -> -11.32 | G11: =$C11 -> -11.32 | H11: =$C11 -> -11.32 | I11: =$C11 -> -11.32 | J11: =$C11 -> -11.32 | K11: =$C11 -> -11.32 | L11: =$C11 -> -11.32 | M11: =$C11+$D11 -> -11.1 | N11: =$C11 -> -11.32
A12: medido MUESTRA | B12: muestra | C12: -5 | D12: 0.22 | E12: =C12 -> -5 | F12: =$C12 -> -5 | G12: =$C12 -> -5 | H12: =$C12 -> -5 | I12: =$C12 -> -5 | J12: =$C12 -> -5 | K12: =$C12 -> -5 | L12: =$C12 -> -5 | M12: =$C12 -> -5 | N12: =$C12+$D12 -> -4.78
C14: CALCULOS
D15: Pendiente | E15: =SLOPE(_xlfn.VSTACK(E5,E7,E9,E11),_xlfn.VSTACK(E4, E6,E8,E10)) -> 1.0532319 | F15: =SLOPE(_xlfn.VSTACK(F5,F7,F9,F11),_xlfn.VSTACK(F4, F6,F8,F10)) -> 1.0375192 | G15: =SLOPE(_xlfn.VSTACK(G5,G7,G9,G11),_xlfn.VSTACK(G4, G6,G8,G10)) -> 1.0690109 | H15: =SLOPE(_xlfn.VSTACK(H5,H7,H9,H11),_xlfn.VSTACK(H4, H6,H8,H10)) -> 1.0471483 | I15: =SLOPE(_xlfn.VSTACK(I5,I7,I9,I11),_xlfn.VSTACK(I4, I6,I8,I10)) -> 1.0574265 | J15: =SLOPE(_xlfn.VSTACK(J5,J7,J9,J11),_xlfn.VSTACK(J4, J6,J8,J10)) -> 1.0619099 | K15: =SLOPE(_xlfn.VSTACK(K5,K7,K9,K11),_xlfn.VSTACK(K4, K6,K8,K10)) -> 1.0447618 | L15: =SLOPE(_xlfn.VSTACK(L5,L7,L9,L11),_xlfn.VSTACK(L4, L6,L8,L10)) -> 1.0658472 | ... N15: =SLOPE(_xlfn.VSTACK(N5,N7,N9,N11),_xlfn.VSTACK(N4, N6,N8,N10)) -> 1.0532319
D16: Interseccion | E16: =+INTERCEPT(_xlfn.VSTACK(E5,E7,E9,E11),_xlfn.VSTACK(E4, E6,E8,E10)) -> 1.8666947 | F16: =+INTERCEPT(_xlfn.VSTACK(F5,F7,F9,F11),_xlfn.VSTACK(F4, F6,F8,F10)) -> 1.6933145 | G16: =+INTERCEPT(_xlfn.VSTACK(G5,G7,G9,G11),_xlfn.VSTACK(G4, G6,G8,G10)) -> 2.038503 | H16: =+INTERCEPT(_xlfn.VSTACK(H5,H7,H9,H11),_xlfn.VSTACK(H4, H6,H8,H10)) -> 1.7640666 | I16: =+INTERCEPT(_xlfn.VSTACK(I5,I7,I9,I11),_xlfn.VSTACK(I4, I6,I8,I10)) -> 1.9527467 | J16: =+INTERCEPT(_xlfn.VSTACK(J5,J7,J9,J11),_xlfn.VSTACK(J4, J6,J8,J10)) -> 1.8725312 | K16: =+INTERCEPT(_xlfn.VSTACK(K5,K7,K9,K11),_xlfn.VSTACK(K4, K6,K8,K10)) -> 1.8589928 | L16: =+INTERCEPT(_xlfn.VSTACK(L5,L7,L9,L11),_xlfn.VSTACK(L4, L6,L8,L10)) -> 1.9014613 | ... N16: =+INTERCEPT(_xlfn.VSTACK(N5,N7,N9,N11),_xlfn.VSTACK(N4, N6,N8,N10)) -> 1.8666947
D17: Resultado perturbado | E17: =+(E12-E16)/E15 -> -6.5196421 | F17: =+(F12-F16)/F15 -> -6.4512679 | G17: =+(G12-G16)/G15 -> -6.5841265 | H17: =+(H12-H16)/H15 -> -6.4595115 | I17: =+(I12-I16)/I15 -> -6.5751583 | J17: =+(J12-J16)/J15 -> -6.4718589 | K17: =+(K12-K16)/K15 -> -6.5651261 | L17: =+(L12-L16)/L15 -> -6.4750945 | ... N17: =+(N12-N16)/N15 -> -6.3107612
E19: DIF caso base | F19: =F17-$E$17 -> 0.06837416 | G19: =G17-$E$17 -> -0.064484468 | H19: =H17-$E$17 -> 0.060130533 | I19: =I17-$E$17 -> -0.055516233 | J19: =J17-$E$17 -> 0.047783131 | K19: =K17-$E$17 -> -0.045484059 | L19: =L17-$E$17 -> 0.044547562 | M19: =M17-$E$17 -> -0.04304487 | N19: =N17-$E$17 -> 0.20888088
E20: VAR est | F20: =POWER(F19,2) -> 0.0046750257 | G20: =POWER(G19,2) -> 0.0041582467 | H20: =POWER(H19,2) -> 0.0036156809 | I20: =POWER(I19,2) -> 0.0030820522 | J20: =POWER(J19,2) -> 0.0022832276 | K20: =POWER(K19,2) -> 0.0020687996 | L20: =POWER(L19,2) -> 0.0019844853 | M20: =POWER(M19,2) -> 0.0018528609 | N20: =POWER(N19,2) -> 0.043631223
E22: VAR COMB | F22: =SUM(F20:N20) -> 0.067351602
E23: u_c | F23: =SQRT(F22) -> 0.25952187
